## 捕获和处理异常

本节将介绍如何使用这三个异常处理部件- `try`，`catch`和`finally`块-写一个异常处理程序。然后，解释了 Java SE 7 中引入的 try-with-resources 语句。try-with-resources 语句特别适用于使用[`Closeable`](https://docs.oracle.com/en/java/javase/17/docs/api/java.base/java/io/Closeable.html)资源（例如流）的情况。

本节的最后一部分通过一个示例来分析各种场景中发生的情况。

以下示例定义并实现了一个名为`ListOfNumbers`. 构造时，`ListOfNumbers`创建一个[`ArrayList`](https://docs.oracle.com/en/java/javase/17/docs/api/java.base/java/util/ArrayList.html)包含 10 个[`Integer`](https://docs.oracle.com/en/java/javase/17/docs/api/java.base/java/lang/Integer.html)元素的 0 到 9 的顺序值。`ListOfNumbers`该类还定义了一个名为 的方法`writeList()`，该方法将数字列表写入名为的文本文件中`OutFile.txt`。此示例使用[`java.io`](https://docs.oracle.com/en/java/javase/17/docs/api/java.base/java/io/package-summary.html)中定义的输出类，这些类在基本 I/O 部分中进行了介绍。

```java
// Note: This class will not compile yet.
import java.io.*;
import java.util.List;
import java.util.ArrayList;

public class ListOfNumbers {

    private List<Integer> list;
    private static final int SIZE = 10;

    public ListOfNumbers () {
        list = new ArrayList<>(SIZE);
        for (int i = 0; i < SIZE; i++) {
            list.add(i);
        }
    }

    public void writeList() {
    // The FileWriter constructor throws IOException, which must be caught.
        PrintWriter out = new PrintWriter(new FileWriter("OutFile.txt"));

        for (int i = 0; i < SIZE; i++) {
            // The get(int) method throws IndexOutOfBoundsException, which must be caught.
            out.println("Value at: " + i + " = " + list.get(i));
        }
        out.close();
    }
}
```

黑体字的第一行是对构造函数的调用。 构造函数在文件上初始化输出流。 如果文件不能打开，构造函数抛出一个IOException。 第二个黑体字行是对ArrayList类的get方法的调用，如果它的参数值太小(小于0)或太大(大于当前ArrayList包含的元素数量)，就会抛出IndexOutOfBoundsException异常。  

如果您尝试编译ListOfNumbers类，编译器将打印一个关于FileWriter构造函数抛出的异常的错误消息。 但是，它不会显示关于get()抛出的异常的错误消息。 原因是构造函数抛出的异常IOException是一个checked异常，而get()方法抛出的异常IndexOutOfBoundsException是一个unchecked异常。  

现在您已经熟悉了ListOfNumbers类以及可以在其中抛出异常的位置，现在可以编写异常处理程序来捕获和处理这些异常了。   

## try块

构建异常处理程序的第一步是将可能引发异常的代码封装在一个`try`块中。通常，`try`块如下所示：

```java
try {
    code
}
catch and finally blocks . . .
```

示例中标记为代码的段包含一个或多个可能引发异常的合法代码行。（`catch`和`finally`块在接下来的两个小节中解释。）

要为ListOfNumbers类中的writeList()方法构造异常处理程序，请将writeList()方法的异常抛出语句包含在一个try块中。 有不止一种方法可以做到这一点。 您可以将可能抛出异常的每一行代码放在其自己的try块中，并为每一行提供单独的异常处理程序。 或者，您可以将所有writeList()代码放在一个try块中，并将多个处理程序与之关联。 下面的清单对整个方法使用了一个try块，因为所讨论的代码非常短。  

```java
private List<Integer> list;
private static final int SIZE = 10;

public void writeList() {
    PrintWriter out = null;
    try {
        System.out.println("Entered try statement");
        out = new PrintWriter(new FileWriter("OutFile.txt"));
        for (int i = 0; i < SIZE; i++) {
            out.println("Value at: " + i + " = " + list.get(i));
        }
    }
    catch and finally blocks  . . .
}
```

如果在try块中发生异常，则该异常由与之关联的异常处理程序处理。 要将异常处理程序与try块关联起来，你必须在它后面放一个catch块; 下一节“catch Blocks”将向您展示如何做到这一点。   

## catch块

通过在try块之后直接提供一个或多个catch块，可以将异常处理程序与try块关联起来。 在try块的末尾和第一个catch块的开头之间不能有任何代码。  

```java
try {

} catch (ExceptionType name) {

} catch (ExceptionType name) {

}
```

每个catch块是一个异常处理程序，处理由其参数指示的异常类型。 参数类型ExceptionType声明处理程序可以处理的异常类型，并且必须是继承自Throwable类的类名。 处理程序可以用name引用异常。  

catch块包含在调用异常处理程序时执行的代码。 当异常处理程序是调用堆栈中第一个ExceptionType与抛出的异常类型匹配的异常处理程序时，运行时系统将调用该异常处理程序。 如果抛出的对象可以合法地分配给异常处理程序的参数，则系统认为它是匹配的。  

以下是该`writeList()`方法的两个异常处理程序：

```java
try {

} catch (IndexOutOfBoundsException e) {
    System.err.println("IndexOutOfBoundsException: " + e.getMessage());
} catch (IOException e) {
    System.err.println("Caught IOException: " + e.getMessage());
}
```

异常处理程序可以做的不仅仅是打印错误消息或停止程序。 它们可以进行错误恢复，提示用户做出决定，或者使用链式异常将错误传播到更高级别的处理程序，如链式异常一节所述。   

## 多捕获异常

使用多捕获模式，您可以使用一个异常处理程序捕获不止一种类型的异常。

在 Java SE 7 及更高版本中，单个`catch`块可以处理多种类型的异常。此功能可以减少代码重复并减少捕获过于广泛的异常的诱惑。

在`catch`子句中，指定block可以处理的异常类型，并用竖线（`|`）分隔每个异常类型：

```java
catch (IOException|SQLException ex) {
    logger.log(ex);
    throw ex;
}
```

注意:如果catch块处理多个异常类型，则catch形参是隐式final。 在本例中，catch参数ex是final，因此不能在catch块中给它赋值。  

## Finally 块

当try块退出时，finally块总是执行。 这确保即使发生意外异常，finally块也会执行。 但最后，它的作用不仅仅是异常处理——它允许程序员避免因返回、继续或中断而意外绕过清理代码。 将清理代码放在finally块中总是一个好习惯，即使没有预料到异常。  

> 注意：如果在执行`try`或`catch`代码时JVM 退出，则该`finally`块可能不会执行。

在这里使用的writeList()方法的try块会打开一个PrintWriter。 程序应该在退出writeList()方法之前关闭该流。 这带来了一个有点复杂的问题，因为writeList()的try块可以以三种方式之一退出。  

1. 新[`FileWriter`](https://docs.oracle.com/en/java/javase/17/docs/api/java.base/java/io/FilterWriter.html)语句失败并抛出一个[`IOException`](https://docs.oracle.com/en/java/javase/17/docs/api/java.base/java/io/IOException.html).
2. 该[`list.get(i)`](https://docs.oracle.com/en/java/javase/17/docs/api/java.base/java/util/List.html#get(int))语句失败并抛出一个[`IndexOutOfBoundsException`](https://docs.oracle.com/en/java/javase/17/docs/api/java.base/java/lang/IndexOutOfBoundsException.html).
3. 一切顺利，`try`块正常退出。

`finally`无论`try`块内发生什么，运行时系统始终执行块内的语句。因此，它是执行清理工作的理想场所。

下面writeList()方法的finally块将清理并关闭PrintWriter。  

```java
finally {
    if (out != null) {
        System.out.println("Closing PrintWriter");
        out.close();
    } else {
        System.out.println("PrintWriter not open");
    }
}
```

> 重要提示:finally块是防止资源泄漏的关键工具。 当关闭文件或恢复资源时，将代码放在finally块中，以确保资源总是被恢复。  
>
> 考虑在这些情况下使用try-with-resources语句，它会在不再需要时自动释放系统资源。 try-with-resources语句部分有更多信息。   

## Try-with-resources 声明

try-with-resources语句是一个try语句，声明一个或多个资源。 资源是在程序使用完后必须关闭的对象。 try-with-resources语句确保在语句结束时关闭每个资源。 任何实现java.lang的对象实现 AutoCloseable，包含所有实现java.io.Closeable的资源。

下面的示例从文件中读取第一行。 它使用BufferedReader的一个实例从文件中读取数据。 BufferedReader是一个资源，在程序使用完后必须关闭:  

```java
static String readFirstLineFromFile(String path) throws IOException {
    try (BufferedReader br =
                   new BufferedReader(new FileReader(path))) {
        return br.readLine();
    }
}
```

在本例中，try-with-resources语句中声明的资源是BufferedReader。 声明语句出现在括号中，紧跟在try关键字之后。 在Java SE 7及以后版本中，BufferedReader类实现了Java .lang. autocloseable接口。 因为BufferedReader实例是在一个try-with-resource语句中声明的，所以不管try语句是正常完成还是突然完成(作为BufferedReader. readline()方法抛出IOException的结果)，它都会被关闭。  

在Java SE 7之前，您可以使用finally块来确保不管try语句是正常完成还是突然完成，资源都是关闭的。 下面的例子使用了finally块而不是try-with-resources语句:  

```java
static String readFirstLineFromFileWithFinallyBlock(String path)
                                                     throws IOException {
    BufferedReader br = new BufferedReader(new FileReader(path));
    try {
        return br.readLine();
    } finally {
        br.close();
    }
}
```

然而，在这个例子中，如果方法readLine()和关闭都抛出异常，那么方法readFirstLineFromFileWithFinallyBlock()抛出从finally块抛出的异常; try块抛出的异常被抑制。 相反，在示例readFirstLineFromFile()中，如果从try块和try with-resources语句中都抛出异常，则readFirstLineFromFile()方法会抛出从try块抛出的异常; 从try with-resources块抛出的异常将被抑制。 在Java SE 7及以后版本中，您可以检索被抑制的异常; 有关更多信息，请参阅抑制异常一节。  

您可以在try-with-resources语句中声明一个或多个资源。 下面的示例检索zip文件zipFileName中打包的文件名，并创建一个包含这些文件名的文本文件:  

```java
public static void writeToFileZipFileContents(String zipFileName,
                                           String outputFileName)
                                           throws java.io.IOException {

    java.nio.charset.Charset charset =
         java.nio.charset.StandardCharsets.US_ASCII;
    java.nio.file.Path outputFilePath =
         java.nio.file.Paths.get(outputFileName);

    // Open zip file and create output file with
    // try-with-resources statement

    try (
        java.util.zip.ZipFile zf =
             new java.util.zip.ZipFile(zipFileName);
        java.io.BufferedWriter writer =
            java.nio.file.Files.newBufferedWriter(outputFilePath, charset)
    ) {
        // Enumerate each entry
        for (java.util.Enumeration entries =
                                zf.entries(); entries.hasMoreElements();) {
            // Get the entry name and write it to the output file
            String newLine = System.getProperty("line.separator");
            String zipEntryName =
                 ((java.util.zip.ZipEntry)entries.nextElement()).getName() +
                 newLine;
            writer.write(zipEntryName, 0, zipEntryName.length());
        }
    }
}
```

在本例中，try-with-resources语句包含两个用分号分隔的声明:ZipFile和BufferedWriter。 当直接跟在它后面的代码块终止时(正常终止或异常终止)，BufferedWriter和ZipFile对象的close()方法将按此顺序自动调用。 请注意，资源的关闭方法的调用顺序与它们创建的顺序相反。  

以下示例使用 try-with-resources 语句自动关闭[`java.sql.Statement`](https://docs.oracle.com/en/java/javase/17/docs/api/java.sql/java/sql/Statement.html)对象：

```java
public static void viewTable(Connection con) throws SQLException {

    String query = "select COF_NAME, SUP_ID, PRICE, SALES, TOTAL from COFFEES";

    try (Statement stmt = con.createStatement()) {
        ResultSet rs = stmt.executeQuery(query);

        while (rs.next()) {
            String coffeeName = rs.getString("COF_NAME");
            int supplierID = rs.getInt("SUP_ID");
            float price = rs.getFloat("PRICE");
            int sales = rs.getInt("SALES");
            int total = rs.getInt("TOTAL");

            System.out.println(coffeeName + ", " + supplierID + ", " +
                               price + ", " + sales + ", " + total);
        }
    } catch (SQLException e) {
        JDBCTutorialUtilities.printSQLException(e);
    }
}
```

本例中使用的资源java.sql.Statement是JDBC 4.1及以后版本API的一部分。  

 注意:一个try-with-resources语句可以像普通的try语句一样有catch和finally块。 在try-with-resources语句中，任何catch或finally块都是在声明的资源被关闭之后运行的。  

## 被抑制的异常

可以从与try with-resources语句关联的代码块中抛出异常。 在示例writeToFileZipFileContents()中，可以从try块抛出一个异常，当try-with-resources语句试图关闭ZipFile和BufferedWriter对象时，最多可以从该语句抛出两个异常。 如果抛出一个异常的try块和一个或多个从try-with-resources声明抛出异常,这些异常抛出try-with-resources声明的镇压,抛出的和异常抛出的块是writeToFileZipFileContents()方法。 您可以通过从try块抛出的异常中调用Throwable.getSuppressed()方法来检索这些被抑制的异常。  

 

## 实现 AutoCloseable 或 Closeable 接口的类

 有关实现AutoCloseable和Closeable接口的类列表，请参阅AutoCloseable和Closeable接口的Javadoc。 Closeable接口扩展了AutoCloseable接口。 Closeable接口的close()方法抛出IOException类型的异常，而AutoCloseable接口的close()方法抛出Exception类型的异常。 因此，AutoCloseable接口的子类可以重写close()方法的这种行为，以抛出特殊的异常，比如IOException，或者根本不抛出异常。  

## **将所有的东西放在一起**

前面的部分描述了如何为ListOfNumbers类中的writeList()方法构造try、catch和finally代码块。 现在，让我们遍历代码并研究会发生什么。  

当所有组件放在一起时，writeList()方法看起来如下所示。  

```java
public void writeList() {
    PrintWriter out = null;

    try {
        System.out.println("Entering" + " try statement");

        out = new PrintWriter(new FileWriter("OutFile.txt"));
        for (int i = 0; i < SIZE; i++) {
            out.println("Value at: " + i + " = " + list.get(i));
        }
    } catch (IndexOutOfBoundsException e) {
        System.err.println("Caught IndexOutOfBoundsException: "
                           +  e.getMessage());

    } catch (IOException e) {
        System.err.println("Caught IOException: " +  e.getMessage());

    } finally {
        if (out != null) {
            System.out.println("Closing PrintWriter");
            out.close();
        }
        else {
            System.out.println("PrintWriter not open");
        }
    }
}
```

正如前面提到的，这个方法的try块有三种不同的退出可能性; 这里有两个。  

1.try语句中的代码失败并抛出异常。 这可能是由新的FileWriter语句引起的IOException，也可能是由for循环中错误的索引值引起的IndexOutOfBoundsException。  

2.一切都成功，try语句正常退出。  

让我们看看在这两种退出可能性期间writeList()方法中发生了什么。  

### 场景一：发生异常

创建FileWriter的语句可能会失败，原因有很多。 例如，如果程序不能创建或写入指定的文件，FileWriter的构造函数将抛出IOException。  

当FileWriter抛出IOException时，运行时系统立即停止执行try块; 正在执行的方法调用未完成。 然后运行时系统开始在方法调用堆栈的顶部搜索适当的异常处理程序。 在这个例子中，当IOException发生时，FileWriter构造函数位于调用堆栈的顶部。 然而，FileWriter构造函数没有适当的异常处理程序，因此运行时系统检查方法调用堆栈中的下一个方法——writeList()方法。 writeList()方法有两个异常处理程序:一个用于IOException，一个用于IndexOutOfBoundsException。  

运行时系统按try语句之后出现的顺序检查writeList()的处理程序。 第一个异常处理程序的参数是IndexOutOfBoundsException。 这与抛出的异常类型不匹配，因此运行时系统检查下一个异常处理程序- IOException。 这与抛出的异常类型相匹配，因此运行时系统将结束对适当异常处理程序的搜索。 既然运行时已经找到了适当的处理程序，那么就执行该catch块中的代码。  

在异常处理程序执行之后，运行时系统将控制权传递给finally块。 finally块中的代码执行，不管上面捕获了什么异常。 在这个场景中，FileWriter从来没有打开过，也不需要关闭。 在finally块执行完之后，程序继续执行finally块之后的第一个语句。  

下面是抛出IOException时ListOfNumbers程序的完整输出。  

```shell
Entering try statement
Caught IOException: OutFile.txt
PrintWriter not open
```



### 场景二：try块正常退出

在这个场景中，try块范围内的所有语句都成功执行，并且没有抛出异常。 执行从try块的末尾落下，运行时系统将控制权传递给finally块。 因为所有操作都是成功的，所以当控件到达finally块时，PrintWriter是打开的，而finally块会关闭PrintWriter。 同样，在finally块执行完之后，程序继续执行finally块之后的第一个语句。  

这是`ListOfNumbers`没有抛出异常时程序的输出。

```shell
Entering try statement
Closing PrintWriter
```